tp-igl-backend  | Traceback (most recent call last):
tp-igl-backend  |   File "/usr/local/lib/python3.8/site-packages/django/db/backends/base/base.py", line 289, in ensure_connection
tp-igl-backend  |     self.connect()
tp-igl-backend  |   File "/usr/local/lib/python3.8/site-packages/django/utils/asyncio.py", line 26, in inner
tp-igl-backend  |     return func(*args, **kwargs)
tp-igl-backend  |   File "/usr/local/lib/python3.8/site-packages/django/db/backends/base/base.py", line 270, in connect
tp-igl-backend  |     self.connection = self.get_new_connection(conn_params)
tp-igl-backend  |   File "/usr/local/lib/python3.8/site-packages/django/utils/asyncio.py", line 26, in inner
tp-igl-backend  |     return func(*args, **kwargs)
tp-igl-backend  |   File "/usr/local/lib/python3.8/site-packages/django/db/backends/mysql/base.py", line 247, in get_new_connection
tp-igl-backend  |     connection = Database.connect(**conn_params)
tp-igl-backend  |   File "/usr/local/lib/python3.8/site-packages/MySQLdb/__init__.py", line 121, in Connect
tp-igl-backend  |     return Connection(*args, **kwargs)
tp-igl-backend  |   File "/usr/local/lib/python3.8/site-packages/MySQLdb/connections.py", line 193, in __init__
tp-igl-backend  |     super().__init__(*args, **kwargs2)
tp-igl-backend  | MySQLdb.OperationalError: (2002, "Can't connect to local server through socket '/run/mysqld/mysqld.sock' (2)")
tp-igl-backend  | 
tp-igl-backend  | The above exception was the direct cause of the following exception:
tp-igl-backend  | 
tp-igl-backend  | Traceback (most recent call last):
tp-igl-backend  |   File "manage.py", line 22, in <module>
tp-igl-backend  |     main()
tp-igl-backend  |   File "manage.py", line 18, in main
tp-igl-backend  |     execute_from_command_line(sys.argv)
tp-igl-backend  |   File "/usr/local/lib/python3.8/site-packages/django/core/management/__init__.py", line 442, in execute_from_command_line
tp-igl-backend  |     utility.execute()
tp-igl-backend  |   File "/usr/local/lib/python3.8/site-packages/django/core/management/__init__.py", line 436, in execute
tp-igl-backend  |     self.fetch_command(subcommand).run_from_argv(self.argv)
tp-igl-backend  |   File "/usr/local/lib/python3.8/site-packages/django/core/management/base.py", line 412, in run_from_argv
tp-igl-backend  |     self.execute(*args, **cmd_options)
tp-igl-backend  |   File "/usr/local/lib/python3.8/site-packages/django/core/management/base.py", line 458, in execute
tp-igl-backend  |     output = self.handle(*args, **options)
tp-igl-backend  |   File "/usr/local/lib/python3.8/site-packages/django/core/management/base.py", line 106, in wrapper
tp-igl-backend  |     res = handle_func(*args, **kwargs)
tp-igl-backend  |   File "/usr/local/lib/python3.8/site-packages/django/core/management/commands/migrate.py", line 100, in handle
tp-igl-backend  |     self.check(databases=[database])
tp-igl-backend  |   File "/usr/local/lib/python3.8/site-packages/django/core/management/base.py", line 485, in check
tp-igl-backend  |     all_issues = checks.run_checks(
tp-igl-backend  |   File "/usr/local/lib/python3.8/site-packages/django/core/checks/registry.py", line 88, in run_checks
tp-igl-backend  |     new_errors = check(app_configs=app_configs, databases=databases)
tp-igl-backend  |   File "/usr/local/lib/python3.8/site-packages/django/core/checks/database.py", line 13, in check_database_backends
tp-igl-backend  |     issues.extend(conn.validation.check(**kwargs))
tp-igl-backend  |   File "/usr/local/lib/python3.8/site-packages/django/db/backends/mysql/validation.py", line 9, in check
tp-igl-backend  |     issues.extend(self._check_sql_mode(**kwargs))
tp-igl-backend  |   File "/usr/local/lib/python3.8/site-packages/django/db/backends/mysql/validation.py", line 14, in _check_sql_mode
tp-igl-backend  |     self.connection.sql_mode & {"STRICT_TRANS_TABLES", "STRICT_ALL_TABLES"}
tp-igl-backend  |   File "/usr/local/lib/python3.8/site-packages/django/utils/functional.py", line 57, in __get__
tp-igl-backend  |     res = instance.__dict__[self.name] = self.func(instance)
tp-igl-backend  |   File "/usr/local/lib/python3.8/site-packages/django/db/backends/mysql/base.py", line 443, in sql_mode
tp-igl-backend  |     sql_mode = self.mysql_server_data["sql_mode"]
tp-igl-backend  |   File "/usr/local/lib/python3.8/site-packages/django/utils/functional.py", line 57, in __get__
tp-igl-backend  |     res = instance.__dict__[self.name] = self.func(instance)
tp-igl-backend  |   File "/usr/local/lib/python3.8/site-packages/django/db/backends/mysql/base.py", line 399, in mysql_server_data
tp-igl-backend  |     with self.temporary_connection() as cursor:
tp-igl-backend  |   File "/usr/local/lib/python3.8/contextlib.py", line 113, in __enter__
tp-igl-backend  |     return next(self.gen)
tp-igl-backend  |   File "/usr/local/lib/python3.8/site-packages/django/db/backends/base/base.py", line 705, in temporary_connection
tp-igl-backend  |     with self.cursor() as cursor:
tp-igl-backend  |   File "/usr/local/lib/python3.8/site-packages/django/utils/asyncio.py", line 26, in inner
tp-igl-backend  |     return func(*args, **kwargs)
tp-igl-backend  |   File "/usr/local/lib/python3.8/site-packages/django/db/backends/base/base.py", line 330, in cursor
tp-igl-backend  |     return self._cursor()
tp-igl-backend  |   File "/usr/local/lib/python3.8/site-packages/django/db/backends/base/base.py", line 306, in _cursor
tp-igl-backend  |     self.ensure_connection()
tp-igl-backend  |   File "/usr/local/lib/python3.8/site-packages/django/utils/asyncio.py", line 26, in inner
tp-igl-backend  |     return func(*args, **kwargs)
tp-igl-backend  |   File "/usr/local/lib/python3.8/site-packages/django/db/backends/base/base.py", line 289, in ensure_connection
tp-igl-backend  |     self.connect()
tp-igl-backend  |   File "/usr/local/lib/python3.8/site-packages/django/db/utils.py", line 91, in __exit__
tp-igl-backend  |     raise dj_exc_value.with_traceback(traceback) from exc_value
tp-igl-backend  |   File "/usr/local/lib/python3.8/site-packages/django/db/backends/base/base.py", line 289, in ensure_connection
tp-igl-backend  |     self.connect()
tp-igl-backend  |   File "/usr/local/lib/python3.8/site-packages/django/utils/asyncio.py", line 26, in inner
tp-igl-backend  |     return func(*args, **kwargs)
tp-igl-backend  |   File "/usr/local/lib/python3.8/site-packages/django/db/backends/base/base.py", line 270, in connect
tp-igl-backend  |     self.connection = self.get_new_connection(conn_params)
tp-igl-backend  |   File "/usr/local/lib/python3.8/site-packages/django/utils/asyncio.py", line 26, in inner
tp-igl-backend  |     return func(*args, **kwargs)
tp-igl-backend  |   File "/usr/local/lib/python3.8/site-packages/django/db/backends/mysql/base.py", line 247, in get_new_connection
tp-igl-backend  |     connection = Database.connect(**conn_params)
tp-igl-backend  |   File "/usr/local/lib/python3.8/site-packages/MySQLdb/__init__.py", line 121, in Connect
tp-igl-backend  |     return Connection(*args, **kwargs)
tp-igl-backend  |   File "/usr/local/lib/python3.8/site-packages/MySQLdb/connections.py", line 193, in __init__
tp-igl-backend  |     super().__init__(*args, **kwargs2)
tp-igl-backend  | django.db.utils.OperationalError: (2002, "Can't connect to local server through socket '/run/mysqld/mysqld.sock' (2)")
tp-igl-backend  | Traceback (most recent call last):
tp-igl-backend  |   File "/usr/local/lib/python3.8/site-packages/django/db/backends/base/base.py", line 289, in ensure_connection
tp-igl-backend  |     self.connect()
tp-igl-backend  |   File "/usr/local/lib/python3.8/site-packages/django/utils/asyncio.py", line 26, in inner
tp-igl-backend  |     return func(*args, **kwargs)
tp-igl-backend  |   File "/usr/local/lib/python3.8/site-packages/django/db/backends/base/base.py", line 270, in connect
tp-igl-backend  |     self.connection = self.get_new_connection(conn_params)
tp-igl-backend  |   File "/usr/local/lib/python3.8/site-packages/django/utils/asyncio.py", line 26, in inner
tp-igl-backend  |     return func(*args, **kwargs)
tp-igl-backend  |   File "/usr/local/lib/python3.8/site-packages/django/db/backends/mysql/base.py", line 247, in get_new_connection
tp-igl-backend  |     connection = Database.connect(**conn_params)
tp-igl-backend  |   File "/usr/local/lib/python3.8/site-packages/MySQLdb/__init__.py", line 121, in Connect
tp-igl-backend  |     return Connection(*args, **kwargs)
tp-igl-backend  |   File "/usr/local/lib/python3.8/site-packages/MySQLdb/connections.py", line 193, in __init__
tp-igl-backend  |     super().__init__(*args, **kwargs2)
tp-igl-backend  | MySQLdb.OperationalError: (2002, "Can't connect to local server through socket '/run/mysqld/mysqld.sock' (2)")
tp-igl-backend  | 
tp-igl-backend  | The above exception was the direct cause of the following exception:
tp-igl-backend  | 
tp-igl-backend  | Traceback (most recent call last):
tp-igl-backend  |   File "manage.py", line 22, in <module>
tp-igl-backend  |     main()
tp-igl-backend  |   File "manage.py", line 18, in main
tp-igl-backend  |     execute_from_command_line(sys.argv)
tp-igl-backend  |   File "/usr/local/lib/python3.8/site-packages/django/core/management/__init__.py", line 442, in execute_from_command_line
tp-igl-backend  |     utility.execute()
tp-igl-backend  |   File "/usr/local/lib/python3.8/site-packages/django/core/management/__init__.py", line 436, in execute
tp-igl-backend  |     self.fetch_command(subcommand).run_from_argv(self.argv)
tp-igl-backend  |   File "/usr/local/lib/python3.8/site-packages/django/core/management/base.py", line 412, in run_from_argv
tp-igl-backend  |     self.execute(*args, **cmd_options)
tp-igl-backend  |   File "/usr/local/lib/python3.8/site-packages/django/core/management/base.py", line 458, in execute
tp-igl-backend  |     output = self.handle(*args, **options)
tp-igl-backend  |   File "/usr/local/lib/python3.8/site-packages/django/core/management/base.py", line 106, in wrapper
tp-igl-backend  |     res = handle_func(*args, **kwargs)
tp-igl-backend  |   File "/usr/local/lib/python3.8/site-packages/django/core/management/commands/migrate.py", line 100, in handle
tp-igl-backend  |     self.check(databases=[database])
tp-igl-backend  |   File "/usr/local/lib/python3.8/site-packages/django/core/management/base.py", line 485, in check
tp-igl-backend  |     all_issues = checks.run_checks(
tp-igl-backend  |   File "/usr/local/lib/python3.8/site-packages/django/core/checks/registry.py", line 88, in run_checks
tp-igl-backend  |     new_errors = check(app_configs=app_configs, databases=databases)
tp-igl-backend  |   File "/usr/local/lib/python3.8/site-packages/django/core/checks/database.py", line 13, in check_database_backends
tp-igl-backend  |     issues.extend(conn.validation.check(**kwargs))
tp-igl-backend  |   File "/usr/local/lib/python3.8/site-packages/django/db/backends/mysql/validation.py", line 9, in check
tp-igl-backend  |     issues.extend(self._check_sql_mode(**kwargs))
tp-igl-backend  |   File "/usr/local/lib/python3.8/site-packages/django/db/backends/mysql/validation.py", line 14, in _check_sql_mode
tp-igl-backend  |     self.connection.sql_mode & {"STRICT_TRANS_TABLES", "STRICT_ALL_TABLES"}
tp-igl-backend  |   File "/usr/local/lib/python3.8/site-packages/django/utils/functional.py", line 57, in __get__
tp-igl-backend  |     res = instance.__dict__[self.name] = self.func(instance)
tp-igl-backend  |   File "/usr/local/lib/python3.8/site-packages/django/db/backends/mysql/base.py", line 443, in sql_mode
tp-igl-backend  |     sql_mode = self.mysql_server_data["sql_mode"]
tp-igl-backend  |   File "/usr/local/lib/python3.8/site-packages/django/utils/functional.py", line 57, in __get__
tp-igl-backend  |     res = instance.__dict__[self.name] = self.func(instance)
tp-igl-backend  |   File "/usr/local/lib/python3.8/site-packages/django/db/backends/mysql/base.py", line 399, in mysql_server_data
tp-igl-backend  |     with self.temporary_connection() as cursor:
tp-igl-backend  |   File "/usr/local/lib/python3.8/contextlib.py", line 113, in __enter__
tp-igl-backend  |     return next(self.gen)
tp-igl-backend  |   File "/usr/local/lib/python3.8/site-packages/django/db/backends/base/base.py", line 705, in temporary_connection
tp-igl-backend  |     with self.cursor() as cursor:
tp-igl-backend  |   File "/usr/local/lib/python3.8/site-packages/django/utils/asyncio.py", line 26, in inner
tp-igl-backend  |     return func(*args, **kwargs)
tp-igl-backend  |   File "/usr/local/lib/python3.8/site-packages/django/db/backends/base/base.py", line 330, in cursor
tp-igl-backend  |     return self._cursor()
tp-igl-backend  |   File "/usr/local/lib/python3.8/site-packages/django/db/backends/base/base.py", line 306, in _cursor
tp-igl-backend  |     self.ensure_connection()
tp-igl-backend  |   File "/usr/local/lib/python3.8/site-packages/django/utils/asyncio.py", line 26, in inner
tp-igl-backend  |     return func(*args, **kwargs)
tp-igl-backend  |   File "/usr/local/lib/python3.8/site-packages/django/db/backends/base/base.py", line 289, in ensure_connection
tp-igl-backend  |     self.connect()
tp-igl-backend  |   File "/usr/local/lib/python3.8/site-packages/django/db/utils.py", line 91, in __exit__
tp-igl-backend  |     raise dj_exc_value.with_traceback(traceback) from exc_value
tp-igl-backend  |   File "/usr/local/lib/python3.8/site-packages/django/db/backends/base/base.py", line 289, in ensure_connection
tp-igl-backend  |     self.connect()
tp-igl-backend  |   File "/usr/local/lib/python3.8/site-packages/django/utils/asyncio.py", line 26, in inner
tp-igl-backend  |     return func(*args, **kwargs)
tp-igl-backend  |   File "/usr/local/lib/python3.8/site-packages/django/db/backends/base/base.py", line 270, in connect
tp-igl-backend  |     self.connection = self.get_new_connection(conn_params)
tp-igl-backend  |   File "/usr/local/lib/python3.8/site-packages/django/utils/asyncio.py", line 26, in inner
tp-igl-backend  |     return func(*args, **kwargs)
tp-igl-backend  |   File "/usr/local/lib/python3.8/site-packages/django/db/backends/mysql/base.py", line 247, in get_new_connection
tp-igl-backend  |     connection = Database.connect(**conn_params)
tp-igl-backend  |   File "/usr/local/lib/python3.8/site-packages/MySQLdb/__init__.py", line 121, in Connect
tp-igl-backend  |     return Connection(*args, **kwargs)
tp-igl-backend  |   File "/usr/local/lib/python3.8/site-packages/MySQLdb/connections.py", line 193, in __init__
tp-igl-backend  |     super().__init__(*args, **kwargs2)
tp-igl-backend  | django.db.utils.OperationalError: (2002, "Can't connect to local server through socket '/run/mysqld/mysqld.sock' (2)")
tp-igl-backend  | Traceback (most recent call last):
tp-igl-backend  |   File "/usr/local/lib/python3.8/site-packages/django/db/backends/base/base.py", line 289, in ensure_connection
tp-igl-backend  |     self.connect()
tp-igl-backend  |   File "/usr/local/lib/python3.8/site-packages/django/utils/asyncio.py", line 26, in inner
tp-igl-backend  |     return func(*args, **kwargs)
tp-igl-backend  |   File "/usr/local/lib/python3.8/site-packages/django/db/backends/base/base.py", line 270, in connect
tp-igl-backend  |     self.connection = self.get_new_connection(conn_params)
tp-igl-backend  |   File "/usr/local/lib/python3.8/site-packages/django/utils/asyncio.py", line 26, in inner
tp-igl-backend  |     return func(*args, **kwargs)
tp-igl-backend  |   File "/usr/local/lib/python3.8/site-packages/django/db/backends/mysql/base.py", line 247, in get_new_connection
tp-igl-backend  |     connection = Database.connect(**conn_params)
tp-igl-backend  |   File "/usr/local/lib/python3.8/site-packages/MySQLdb/__init__.py", line 121, in Connect
tp-igl-backend  |     return Connection(*args, **kwargs)
tp-igl-backend  |   File "/usr/local/lib/python3.8/site-packages/MySQLdb/connections.py", line 193, in __init__
tp-igl-backend  |     super().__init__(*args, **kwargs2)
tp-igl-backend  | MySQLdb.OperationalError: (2002, "Can't connect to local server through socket '/run/mysqld/mysqld.sock' (2)")
tp-igl-backend  | 
tp-igl-backend  | The above exception was the direct cause of the following exception:
tp-igl-backend  | 
tp-igl-backend  | Traceback (most recent call last):
tp-igl-backend  |   File "manage.py", line 22, in <module>
tp-igl-backend  |     main()
tp-igl-backend  |   File "manage.py", line 18, in main
tp-igl-backend  |     execute_from_command_line(sys.argv)
tp-igl-backend  |   File "/usr/local/lib/python3.8/site-packages/django/core/management/__init__.py", line 442, in execute_from_command_line
tp-igl-backend  |     utility.execute()
tp-igl-backend  |   File "/usr/local/lib/python3.8/site-packages/django/core/management/__init__.py", line 436, in execute
tp-igl-backend  |     self.fetch_command(subcommand).run_from_argv(self.argv)
tp-igl-backend  |   File "/usr/local/lib/python3.8/site-packages/django/core/management/base.py", line 412, in run_from_argv
tp-igl-backend  |     self.execute(*args, **cmd_options)
tp-igl-backend  |   File "/usr/local/lib/python3.8/site-packages/django/core/management/base.py", line 458, in execute
tp-igl-backend  |     output = self.handle(*args, **options)
tp-igl-backend  |   File "/usr/local/lib/python3.8/site-packages/django/core/management/base.py", line 106, in wrapper
tp-igl-backend  |     res = handle_func(*args, **kwargs)
tp-igl-backend  |   File "/usr/local/lib/python3.8/site-packages/django/core/management/commands/migrate.py", line 100, in handle
tp-igl-backend  |     self.check(databases=[database])
tp-igl-backend  |   File "/usr/local/lib/python3.8/site-packages/django/core/management/base.py", line 485, in check
tp-igl-backend  |     all_issues = checks.run_checks(
tp-igl-backend  |   File "/usr/local/lib/python3.8/site-packages/django/core/checks/registry.py", line 88, in run_checks
tp-igl-backend  |     new_errors = check(app_configs=app_configs, databases=databases)
tp-igl-backend  |   File "/usr/local/lib/python3.8/site-packages/django/core/checks/database.py", line 13, in check_database_backends
tp-igl-backend  |     issues.extend(conn.validation.check(**kwargs))
tp-igl-backend  |   File "/usr/local/lib/python3.8/site-packages/django/db/backends/mysql/validation.py", line 9, in check
tp-igl-backend  |     issues.extend(self._check_sql_mode(**kwargs))
tp-igl-backend  |   File "/usr/local/lib/python3.8/site-packages/django/db/backends/mysql/validation.py", line 14, in _check_sql_mode
tp-igl-backend  |     self.connection.sql_mode & {"STRICT_TRANS_TABLES", "STRICT_ALL_TABLES"}
tp-igl-backend  |   File "/usr/local/lib/python3.8/site-packages/django/utils/functional.py", line 57, in __get__
tp-igl-backend  |     res = instance.__dict__[self.name] = self.func(instance)
tp-igl-backend  |   File "/usr/local/lib/python3.8/site-packages/django/db/backends/mysql/base.py", line 443, in sql_mode
tp-igl-backend  |     sql_mode = self.mysql_server_data["sql_mode"]
tp-igl-backend  |   File "/usr/local/lib/python3.8/site-packages/django/utils/functional.py", line 57, in __get__
tp-igl-backend  |     res = instance.__dict__[self.name] = self.func(instance)
tp-igl-backend  |   File "/usr/local/lib/python3.8/site-packages/django/db/backends/mysql/base.py", line 399, in mysql_server_data
tp-igl-backend  |     with self.temporary_connection() as cursor:
tp-igl-backend  |   File "/usr/local/lib/python3.8/contextlib.py", line 113, in __enter__
tp-igl-backend  |     return next(self.gen)
tp-igl-backend  |   File "/usr/local/lib/python3.8/site-packages/django/db/backends/base/base.py", line 705, in temporary_connection
tp-igl-backend  |     with self.cursor() as cursor:
tp-igl-backend  |   File "/usr/local/lib/python3.8/site-packages/django/utils/asyncio.py", line 26, in inner
tp-igl-backend  |     return func(*args, **kwargs)
tp-igl-backend  |   File "/usr/local/lib/python3.8/site-packages/django/db/backends/base/base.py", line 330, in cursor
tp-igl-backend  |     return self._cursor()
tp-igl-backend  |   File "/usr/local/lib/python3.8/site-packages/django/db/backends/base/base.py", line 306, in _cursor
tp-igl-backend  |     self.ensure_connection()
tp-igl-backend  |   File "/usr/local/lib/python3.8/site-packages/django/utils/asyncio.py", line 26, in inner
tp-igl-backend  |     return func(*args, **kwargs)
tp-igl-backend  |   File "/usr/local/lib/python3.8/site-packages/django/db/backends/base/base.py", line 289, in ensure_connection
tp-igl-backend  |     self.connect()
tp-igl-backend  |   File "/usr/local/lib/python3.8/site-packages/django/db/utils.py", line 91, in __exit__
tp-igl-backend  |     raise dj_exc_value.with_traceback(traceback) from exc_value
tp-igl-backend  |   File "/usr/local/lib/python3.8/site-packages/django/db/backends/base/base.py", line 289, in ensure_connection
tp-igl-backend  |     self.connect()
tp-igl-backend  |   File "/usr/local/lib/python3.8/site-packages/django/utils/asyncio.py", line 26, in inner
tp-igl-backend  |     return func(*args, **kwargs)
tp-igl-backend  |   File "/usr/local/lib/python3.8/site-packages/django/db/backends/base/base.py", line 270, in connect
tp-igl-backend  |     self.connection = self.get_new_connection(conn_params)
tp-igl-backend  |   File "/usr/local/lib/python3.8/site-packages/django/utils/asyncio.py", line 26, in inner
tp-igl-backend  |     return func(*args, **kwargs)
tp-igl-backend  |   File "/usr/local/lib/python3.8/site-packages/django/db/backends/mysql/base.py", line 247, in get_new_connection
tp-igl-backend  |     connection = Database.connect(**conn_params)
tp-igl-backend  |   File "/usr/local/lib/python3.8/site-packages/MySQLdb/__init__.py", line 121, in Connect
tp-igl-backend  |     return Connection(*args, **kwargs)
tp-igl-backend  |   File "/usr/local/lib/python3.8/site-packages/MySQLdb/connections.py", line 193, in __init__
tp-igl-backend  |     super().__init__(*args, **kwargs2)
tp-igl-backend  | django.db.utils.OperationalError: (2002, "Can't connect to local server through socket '/run/mysqld/mysqld.sock' (2)")
tp-igl-backend  | Traceback (most recent call last):
tp-igl-backend  |   File "/usr/local/lib/python3.8/site-packages/django/db/backends/base/base.py", line 289, in ensure_connection
tp-igl-backend  |     self.connect()
tp-igl-backend  |   File "/usr/local/lib/python3.8/site-packages/django/utils/asyncio.py", line 26, in inner
tp-igl-backend  |     return func(*args, **kwargs)
tp-igl-backend  |   File "/usr/local/lib/python3.8/site-packages/django/db/backends/base/base.py", line 270, in connect
tp-igl-backend  |     self.connection = self.get_new_connection(conn_params)
tp-igl-backend  |   File "/usr/local/lib/python3.8/site-packages/django/utils/asyncio.py", line 26, in inner
tp-igl-backend  |     return func(*args, **kwargs)
tp-igl-backend  |   File "/usr/local/lib/python3.8/site-packages/django/db/backends/mysql/base.py", line 247, in get_new_connection
tp-igl-backend  |     connection = Database.connect(**conn_params)
tp-igl-backend  |   File "/usr/local/lib/python3.8/site-packages/MySQLdb/__init__.py", line 121, in Connect
tp-igl-backend  |     return Connection(*args, **kwargs)
tp-igl-backend  |   File "/usr/local/lib/python3.8/site-packages/MySQLdb/connections.py", line 193, in __init__
tp-igl-backend  |     super().__init__(*args, **kwargs2)
tp-igl-backend  | MySQLdb.OperationalError: (2002, "Can't connect to local server through socket '/run/mysqld/mysqld.sock' (2)")
tp-igl-backend  | 
tp-igl-backend  | The above exception was the direct cause of the following exception:
tp-igl-backend  | 
tp-igl-backend  | Traceback (most recent call last):
tp-igl-backend  |   File "manage.py", line 22, in <module>
tp-igl-backend  |     main()
tp-igl-backend  |   File "manage.py", line 18, in main
tp-igl-backend  |     execute_from_command_line(sys.argv)
tp-igl-backend  |   File "/usr/local/lib/python3.8/site-packages/django/core/management/__init__.py", line 442, in execute_from_command_line
tp-igl-backend  |     utility.execute()
tp-igl-backend  |   File "/usr/local/lib/python3.8/site-packages/django/core/management/__init__.py", line 436, in execute
tp-igl-backend  |     self.fetch_command(subcommand).run_from_argv(self.argv)
tp-igl-backend  |   File "/usr/local/lib/python3.8/site-packages/django/core/management/base.py", line 412, in run_from_argv
tp-igl-backend  |     self.execute(*args, **cmd_options)
tp-igl-backend  |   File "/usr/local/lib/python3.8/site-packages/django/core/management/base.py", line 458, in execute
tp-igl-backend  |     output = self.handle(*args, **options)
tp-igl-backend  |   File "/usr/local/lib/python3.8/site-packages/django/core/management/base.py", line 106, in wrapper
tp-igl-backend  |     res = handle_func(*args, **kwargs)
tp-igl-backend  |   File "/usr/local/lib/python3.8/site-packages/django/core/management/commands/migrate.py", line 100, in handle
tp-igl-backend  |     self.check(databases=[database])
tp-igl-backend  |   File "/usr/local/lib/python3.8/site-packages/django/core/management/base.py", line 485, in check
tp-igl-backend  |     all_issues = checks.run_checks(
tp-igl-backend  |   File "/usr/local/lib/python3.8/site-packages/django/core/checks/registry.py", line 88, in run_checks
tp-igl-backend  |     new_errors = check(app_configs=app_configs, databases=databases)
tp-igl-backend  |   File "/usr/local/lib/python3.8/site-packages/django/core/checks/database.py", line 13, in check_database_backends
tp-igl-backend  |     issues.extend(conn.validation.check(**kwargs))
tp-igl-backend  |   File "/usr/local/lib/python3.8/site-packages/django/db/backends/mysql/validation.py", line 9, in check
tp-igl-backend  |     issues.extend(self._check_sql_mode(**kwargs))
tp-igl-backend  |   File "/usr/local/lib/python3.8/site-packages/django/db/backends/mysql/validation.py", line 14, in _check_sql_mode
tp-igl-backend  |     self.connection.sql_mode & {"STRICT_TRANS_TABLES", "STRICT_ALL_TABLES"}
tp-igl-backend  |   File "/usr/local/lib/python3.8/site-packages/django/utils/functional.py", line 57, in __get__
tp-igl-backend  |     res = instance.__dict__[self.name] = self.func(instance)
tp-igl-backend  |   File "/usr/local/lib/python3.8/site-packages/django/db/backends/mysql/base.py", line 443, in sql_mode
tp-igl-backend  |     sql_mode = self.mysql_server_data["sql_mode"]
tp-igl-backend  |   File "/usr/local/lib/python3.8/site-packages/django/utils/functional.py", line 57, in __get__
tp-igl-backend  |     res = instance.__dict__[self.name] = self.func(instance)
tp-igl-backend  |   File "/usr/local/lib/python3.8/site-packages/django/db/backends/mysql/base.py", line 399, in mysql_server_data
tp-igl-backend  |     with self.temporary_connection() as cursor:
tp-igl-backend  |   File "/usr/local/lib/python3.8/contextlib.py", line 113, in __enter__
tp-igl-backend  |     return next(self.gen)
tp-igl-backend  |   File "/usr/local/lib/python3.8/site-packages/django/db/backends/base/base.py", line 705, in temporary_connection
tp-igl-backend  |     with self.cursor() as cursor:
tp-igl-backend  |   File "/usr/local/lib/python3.8/site-packages/django/utils/asyncio.py", line 26, in inner
tp-igl-backend  |     return func(*args, **kwargs)
tp-igl-backend  |   File "/usr/local/lib/python3.8/site-packages/django/db/backends/base/base.py", line 330, in cursor
tp-igl-backend  |     return self._cursor()
tp-igl-backend  |   File "/usr/local/lib/python3.8/site-packages/django/db/backends/base/base.py", line 306, in _cursor
tp-igl-backend  |     self.ensure_connection()
tp-igl-backend  |   File "/usr/local/lib/python3.8/site-packages/django/utils/asyncio.py", line 26, in inner
tp-igl-backend  |     return func(*args, **kwargs)
tp-igl-backend  |   File "/usr/local/lib/python3.8/site-packages/django/db/backends/base/base.py", line 289, in ensure_connection
tp-igl-backend  |     self.connect()
tp-igl-backend  |   File "/usr/local/lib/python3.8/site-packages/django/db/utils.py", line 91, in __exit__
tp-igl-backend  |     raise dj_exc_value.with_traceback(traceback) from exc_value
tp-igl-backend  |   File "/usr/local/lib/python3.8/site-packages/django/db/backends/base/base.py", line 289, in ensure_connection
tp-igl-backend  |     self.connect()
tp-igl-backend  |   File "/usr/local/lib/python3.8/site-packages/django/utils/asyncio.py", line 26, in inner
tp-igl-backend  |     return func(*args, **kwargs)
tp-igl-backend  |   File "/usr/local/lib/python3.8/site-packages/django/db/backends/base/base.py", line 270, in connect
tp-igl-backend  |     self.connection = self.get_new_connection(conn_params)
tp-igl-backend  |   File "/usr/local/lib/python3.8/site-packages/django/utils/asyncio.py", line 26, in inner
tp-igl-backend  |     return func(*args, **kwargs)
tp-igl-backend  |   File "/usr/local/lib/python3.8/site-packages/django/db/backends/mysql/base.py", line 247, in get_new_connection
tp-igl-backend  |     connection = Database.connect(**conn_params)
tp-igl-backend  |   File "/usr/local/lib/python3.8/site-packages/MySQLdb/__init__.py", line 121, in Connect
tp-igl-backend  |     return Connection(*args, **kwargs)
tp-igl-backend  |   File "/usr/local/lib/python3.8/site-packages/MySQLdb/connections.py", line 193, in __init__
tp-igl-backend  |     super().__init__(*args, **kwargs2)
tp-igl-backend  | django.db.utils.OperationalError: (2002, "Can't connect to local server through socket '/run/mysqld/mysqld.sock' (2)")
tp-igl-backend  | Traceback (most recent call last):
tp-igl-backend  |   File "/usr/local/lib/python3.8/site-packages/django/db/backends/base/base.py", line 289, in ensure_connection
tp-igl-backend  |     self.connect()
tp-igl-backend  |   File "/usr/local/lib/python3.8/site-packages/django/utils/asyncio.py", line 26, in inner
tp-igl-backend  |     return func(*args, **kwargs)
tp-igl-backend  |   File "/usr/local/lib/python3.8/site-packages/django/db/backends/base/base.py", line 270, in connect
tp-igl-backend  |     self.connection = self.get_new_connection(conn_params)
tp-igl-backend  |   File "/usr/local/lib/python3.8/site-packages/django/utils/asyncio.py", line 26, in inner
tp-igl-backend  |     return func(*args, **kwargs)
tp-igl-backend  |   File "/usr/local/lib/python3.8/site-packages/django/db/backends/mysql/base.py", line 247, in get_new_connection
tp-igl-backend  |     connection = Database.connect(**conn_params)
tp-igl-backend  |   File "/usr/local/lib/python3.8/site-packages/MySQLdb/__init__.py", line 121, in Connect
tp-igl-backend  |     return Connection(*args, **kwargs)
tp-igl-backend  |   File "/usr/local/lib/python3.8/site-packages/MySQLdb/connections.py", line 193, in __init__
tp-igl-backend  |     super().__init__(*args, **kwargs2)
tp-igl-backend  | MySQLdb.OperationalError: (2002, "Can't connect to local server through socket '/run/mysqld/mysqld.sock' (2)")
tp-igl-backend  | 
tp-igl-backend  | The above exception was the direct cause of the following exception:
tp-igl-backend  | 
tp-igl-backend  | Traceback (most recent call last):
tp-igl-backend  |   File "manage.py", line 22, in <module>
tp-igl-backend  |     main()
tp-igl-backend  |   File "manage.py", line 18, in main
tp-igl-backend  |     execute_from_command_line(sys.argv)
tp-igl-backend  |   File "/usr/local/lib/python3.8/site-packages/django/core/management/__init__.py", line 442, in execute_from_command_line
tp-igl-backend  |     utility.execute()
tp-igl-backend  |   File "/usr/local/lib/python3.8/site-packages/django/core/management/__init__.py", line 436, in execute
tp-igl-backend  |     self.fetch_command(subcommand).run_from_argv(self.argv)
tp-igl-backend  |   File "/usr/local/lib/python3.8/site-packages/django/core/management/base.py", line 412, in run_from_argv
tp-igl-backend  |     self.execute(*args, **cmd_options)
tp-igl-backend  |   File "/usr/local/lib/python3.8/site-packages/django/core/management/base.py", line 458, in execute
tp-igl-backend  |     output = self.handle(*args, **options)
tp-igl-backend  |   File "/usr/local/lib/python3.8/site-packages/django/core/management/base.py", line 106, in wrapper
tp-igl-backend  |     res = handle_func(*args, **kwargs)
tp-igl-backend  |   File "/usr/local/lib/python3.8/site-packages/django/core/management/commands/migrate.py", line 100, in handle
tp-igl-backend  |     self.check(databases=[database])
tp-igl-backend  |   File "/usr/local/lib/python3.8/site-packages/django/core/management/base.py", line 485, in check
tp-igl-backend  |     all_issues = checks.run_checks(
tp-igl-backend  |   File "/usr/local/lib/python3.8/site-packages/django/core/checks/registry.py", line 88, in run_checks
tp-igl-backend  |     new_errors = check(app_configs=app_configs, databases=databases)
tp-igl-backend  |   File "/usr/local/lib/python3.8/site-packages/django/core/checks/database.py", line 13, in check_database_backends
tp-igl-backend  |     issues.extend(conn.validation.check(**kwargs))
tp-igl-backend  |   File "/usr/local/lib/python3.8/site-packages/django/db/backends/mysql/validation.py", line 9, in check
tp-igl-backend  |     issues.extend(self._check_sql_mode(**kwargs))
tp-igl-backend  |   File "/usr/local/lib/python3.8/site-packages/django/db/backends/mysql/validation.py", line 14, in _check_sql_mode
tp-igl-backend  |     self.connection.sql_mode & {"STRICT_TRANS_TABLES", "STRICT_ALL_TABLES"}
tp-igl-backend  |   File "/usr/local/lib/python3.8/site-packages/django/utils/functional.py", line 57, in __get__
tp-igl-backend  |     res = instance.__dict__[self.name] = self.func(instance)
tp-igl-backend  |   File "/usr/local/lib/python3.8/site-packages/django/db/backends/mysql/base.py", line 443, in sql_mode
tp-igl-backend  |     sql_mode = self.mysql_server_data["sql_mode"]
tp-igl-backend  |   File "/usr/local/lib/python3.8/site-packages/django/utils/functional.py", line 57, in __get__
tp-igl-backend  |     res = instance.__dict__[self.name] = self.func(instance)
tp-igl-backend  |   File "/usr/local/lib/python3.8/site-packages/django/db/backends/mysql/base.py", line 399, in mysql_server_data
tp-igl-backend  |     with self.temporary_connection() as cursor:
tp-igl-backend  |   File "/usr/local/lib/python3.8/contextlib.py", line 113, in __enter__
tp-igl-backend  |     return next(self.gen)
tp-igl-backend  |   File "/usr/local/lib/python3.8/site-packages/django/db/backends/base/base.py", line 705, in temporary_connection
tp-igl-backend  |     with self.cursor() as cursor:
tp-igl-backend  |   File "/usr/local/lib/python3.8/site-packages/django/utils/asyncio.py", line 26, in inner
tp-igl-backend  |     return func(*args, **kwargs)
tp-igl-backend  |   File "/usr/local/lib/python3.8/site-packages/django/db/backends/base/base.py", line 330, in cursor
tp-igl-backend  |     return self._cursor()
tp-igl-backend  |   File "/usr/local/lib/python3.8/site-packages/django/db/backends/base/base.py", line 306, in _cursor
tp-igl-backend  |     self.ensure_connection()
tp-igl-backend  |   File "/usr/local/lib/python3.8/site-packages/django/utils/asyncio.py", line 26, in inner
tp-igl-backend  |     return func(*args, **kwargs)
tp-igl-backend  |   File "/usr/local/lib/python3.8/site-packages/django/db/backends/base/base.py", line 289, in ensure_connection
tp-igl-backend  |     self.connect()
tp-igl-backend  |   File "/usr/local/lib/python3.8/site-packages/django/db/utils.py", line 91, in __exit__
tp-igl-backend  |     raise dj_exc_value.with_traceback(traceback) from exc_value
tp-igl-backend  |   File "/usr/local/lib/python3.8/site-packages/django/db/backends/base/base.py", line 289, in ensure_connection
tp-igl-backend  |     self.connect()
tp-igl-backend  |   File "/usr/local/lib/python3.8/site-packages/django/utils/asyncio.py", line 26, in inner
tp-igl-backend  |     return func(*args, **kwargs)
tp-igl-backend  |   File "/usr/local/lib/python3.8/site-packages/django/db/backends/base/base.py", line 270, in connect
tp-igl-backend  |     self.connection = self.get_new_connection(conn_params)
tp-igl-backend  |   File "/usr/local/lib/python3.8/site-packages/django/utils/asyncio.py", line 26, in inner
tp-igl-backend  |     return func(*args, **kwargs)
tp-igl-backend  |   File "/usr/local/lib/python3.8/site-packages/django/db/backends/mysql/base.py", line 247, in get_new_connection
tp-igl-backend  |     connection = Database.connect(**conn_params)
tp-igl-backend  |   File "/usr/local/lib/python3.8/site-packages/MySQLdb/__init__.py", line 121, in Connect
tp-igl-backend  |     return Connection(*args, **kwargs)
tp-igl-backend  |   File "/usr/local/lib/python3.8/site-packages/MySQLdb/connections.py", line 193, in __init__
tp-igl-backend  |     super().__init__(*args, **kwargs2)
tp-igl-backend  | django.db.utils.OperationalError: (2002, "Can't connect to local server through socket '/run/mysqld/mysqld.sock' (2)")
tp-igl-backend  | Traceback (most recent call last):
tp-igl-backend  |   File "/usr/local/lib/python3.8/site-packages/django/db/backends/base/base.py", line 289, in ensure_connection
tp-igl-backend  |     self.connect()
tp-igl-backend  |   File "/usr/local/lib/python3.8/site-packages/django/utils/asyncio.py", line 26, in inner
tp-igl-backend  |     return func(*args, **kwargs)
tp-igl-backend  |   File "/usr/local/lib/python3.8/site-packages/django/db/backends/base/base.py", line 270, in connect
tp-igl-backend  |     self.connection = self.get_new_connection(conn_params)
tp-igl-backend  |   File "/usr/local/lib/python3.8/site-packages/django/utils/asyncio.py", line 26, in inner
tp-igl-backend  |     return func(*args, **kwargs)
tp-igl-backend  |   File "/usr/local/lib/python3.8/site-packages/django/db/backends/mysql/base.py", line 247, in get_new_connection
tp-igl-backend  |     connection = Database.connect(**conn_params)
tp-igl-backend  |   File "/usr/local/lib/python3.8/site-packages/MySQLdb/__init__.py", line 121, in Connect
tp-igl-backend  |     return Connection(*args, **kwargs)
tp-igl-backend  |   File "/usr/local/lib/python3.8/site-packages/MySQLdb/connections.py", line 193, in __init__
tp-igl-backend  |     super().__init__(*args, **kwargs2)
tp-igl-backend  | MySQLdb.OperationalError: (2002, "Can't connect to local server through socket '/run/mysqld/mysqld.sock' (2)")
tp-igl-backend  | 
tp-igl-backend  | The above exception was the direct cause of the following exception:
tp-igl-backend  | 
tp-igl-backend  | Traceback (most recent call last):
tp-igl-backend  |   File "manage.py", line 22, in <module>
tp-igl-backend  |     main()
tp-igl-backend  |   File "manage.py", line 18, in main
tp-igl-backend  |     execute_from_command_line(sys.argv)
tp-igl-backend  |   File "/usr/local/lib/python3.8/site-packages/django/core/management/__init__.py", line 442, in execute_from_command_line
tp-igl-backend  |     utility.execute()
tp-igl-backend  |   File "/usr/local/lib/python3.8/site-packages/django/core/management/__init__.py", line 436, in execute
tp-igl-backend  |     self.fetch_command(subcommand).run_from_argv(self.argv)
tp-igl-backend  |   File "/usr/local/lib/python3.8/site-packages/django/core/management/base.py", line 412, in run_from_argv
tp-igl-backend  |     self.execute(*args, **cmd_options)
tp-igl-backend  |   File "/usr/local/lib/python3.8/site-packages/django/core/management/base.py", line 458, in execute
tp-igl-backend  |     output = self.handle(*args, **options)
tp-igl-backend  |   File "/usr/local/lib/python3.8/site-packages/django/core/management/base.py", line 106, in wrapper
tp-igl-backend  |     res = handle_func(*args, **kwargs)
tp-igl-backend  |   File "/usr/local/lib/python3.8/site-packages/django/core/management/commands/migrate.py", line 100, in handle
tp-igl-backend  |     self.check(databases=[database])
tp-igl-backend  |   File "/usr/local/lib/python3.8/site-packages/django/core/management/base.py", line 485, in check
tp-igl-backend  |     all_issues = checks.run_checks(
tp-igl-backend  |   File "/usr/local/lib/python3.8/site-packages/django/core/checks/registry.py", line 88, in run_checks
tp-igl-backend  |     new_errors = check(app_configs=app_configs, databases=databases)
tp-igl-backend  |   File "/usr/local/lib/python3.8/site-packages/django/core/checks/database.py", line 13, in check_database_backends
tp-igl-backend  |     issues.extend(conn.validation.check(**kwargs))
tp-igl-backend  |   File "/usr/local/lib/python3.8/site-packages/django/db/backends/mysql/validation.py", line 9, in check
tp-igl-backend  |     issues.extend(self._check_sql_mode(**kwargs))
tp-igl-backend  |   File "/usr/local/lib/python3.8/site-packages/django/db/backends/mysql/validation.py", line 14, in _check_sql_mode
tp-igl-backend  |     self.connection.sql_mode & {"STRICT_TRANS_TABLES", "STRICT_ALL_TABLES"}
tp-igl-backend  |   File "/usr/local/lib/python3.8/site-packages/django/utils/functional.py", line 57, in __get__
tp-igl-backend  |     res = instance.__dict__[self.name] = self.func(instance)
tp-igl-backend  |   File "/usr/local/lib/python3.8/site-packages/django/db/backends/mysql/base.py", line 443, in sql_mode
tp-igl-backend  |     sql_mode = self.mysql_server_data["sql_mode"]
tp-igl-backend  |   File "/usr/local/lib/python3.8/site-packages/django/utils/functional.py", line 57, in __get__
tp-igl-backend  |     res = instance.__dict__[self.name] = self.func(instance)
tp-igl-backend  |   File "/usr/local/lib/python3.8/site-packages/django/db/backends/mysql/base.py", line 399, in mysql_server_data
tp-igl-backend  |     with self.temporary_connection() as cursor:
tp-igl-backend  |   File "/usr/local/lib/python3.8/contextlib.py", line 113, in __enter__
tp-igl-backend  |     return next(self.gen)
tp-igl-backend  |   File "/usr/local/lib/python3.8/site-packages/django/db/backends/base/base.py", line 705, in temporary_connection
tp-igl-backend  |     with self.cursor() as cursor:
tp-igl-backend  |   File "/usr/local/lib/python3.8/site-packages/django/utils/asyncio.py", line 26, in inner
tp-igl-backend  |     return func(*args, **kwargs)
tp-igl-backend  |   File "/usr/local/lib/python3.8/site-packages/django/db/backends/base/base.py", line 330, in cursor
tp-igl-backend  |     return self._cursor()
tp-igl-backend  |   File "/usr/local/lib/python3.8/site-packages/django/db/backends/base/base.py", line 306, in _cursor
tp-igl-backend  |     self.ensure_connection()
tp-igl-backend  |   File "/usr/local/lib/python3.8/site-packages/django/utils/asyncio.py", line 26, in inner
tp-igl-backend  |     return func(*args, **kwargs)
tp-igl-backend  |   File "/usr/local/lib/python3.8/site-packages/django/db/backends/base/base.py", line 289, in ensure_connection
tp-igl-backend  |     self.connect()
tp-igl-backend  |   File "/usr/local/lib/python3.8/site-packages/django/db/utils.py", line 91, in __exit__
tp-igl-backend  |     raise dj_exc_value.with_traceback(traceback) from exc_value
tp-igl-backend  |   File "/usr/local/lib/python3.8/site-packages/django/db/backends/base/base.py", line 289, in ensure_connection
tp-igl-backend  |     self.connect()
tp-igl-backend  |   File "/usr/local/lib/python3.8/site-packages/django/utils/asyncio.py", line 26, in inner
tp-igl-backend  |     return func(*args, **kwargs)
tp-igl-backend  |   File "/usr/local/lib/python3.8/site-packages/django/db/backends/base/base.py", line 270, in connect
tp-igl-backend  |     self.connection = self.get_new_connection(conn_params)
tp-igl-backend  |   File "/usr/local/lib/python3.8/site-packages/django/utils/asyncio.py", line 26, in inner
tp-igl-backend  |     return func(*args, **kwargs)
tp-igl-backend  |   File "/usr/local/lib/python3.8/site-packages/django/db/backends/mysql/base.py", line 247, in get_new_connection
tp-igl-backend  |     connection = Database.connect(**conn_params)
tp-igl-backend  |   File "/usr/local/lib/python3.8/site-packages/MySQLdb/__init__.py", line 121, in Connect
tp-igl-backend  |     return Connection(*args, **kwargs)
tp-igl-backend  |   File "/usr/local/lib/python3.8/site-packages/MySQLdb/connections.py", line 193, in __init__
tp-igl-backend  |     super().__init__(*args, **kwargs2)
tp-igl-backend  | django.db.utils.OperationalError: (2002, "Can't connect to local server through socket '/run/mysqld/mysqld.sock' (2)")
tp-igl-backend  | Traceback (most recent call last):
tp-igl-backend  |   File "/usr/local/lib/python3.8/site-packages/django/db/backends/base/base.py", line 289, in ensure_connection
tp-igl-backend  |     self.connect()
tp-igl-backend  |   File "/usr/local/lib/python3.8/site-packages/django/utils/asyncio.py", line 26, in inner
tp-igl-backend  |     return func(*args, **kwargs)
tp-igl-backend  |   File "/usr/local/lib/python3.8/site-packages/django/db/backends/base/base.py", line 270, in connect
tp-igl-backend  |     self.connection = self.get_new_connection(conn_params)
tp-igl-backend  |   File "/usr/local/lib/python3.8/site-packages/django/utils/asyncio.py", line 26, in inner
tp-igl-backend  |     return func(*args, **kwargs)
tp-igl-backend  |   File "/usr/local/lib/python3.8/site-packages/django/db/backends/mysql/base.py", line 247, in get_new_connection
tp-igl-backend  |     connection = Database.connect(**conn_params)
tp-igl-backend  |   File "/usr/local/lib/python3.8/site-packages/MySQLdb/__init__.py", line 121, in Connect
tp-igl-backend  |     return Connection(*args, **kwargs)
tp-igl-backend  |   File "/usr/local/lib/python3.8/site-packages/MySQLdb/connections.py", line 193, in __init__
tp-igl-backend  |     super().__init__(*args, **kwargs2)
tp-igl-backend  | MySQLdb.OperationalError: (2002, "Can't connect to local server through socket '/run/mysqld/mysqld.sock' (2)")
tp-igl-backend  | 
tp-igl-backend  | The above exception was the direct cause of the following exception:
tp-igl-backend  | 
tp-igl-backend  | Traceback (most recent call last):
tp-igl-backend  |   File "manage.py", line 22, in <module>
tp-igl-backend  |     main()
tp-igl-backend  |   File "manage.py", line 18, in main
tp-igl-backend  |     execute_from_command_line(sys.argv)
tp-igl-backend  |   File "/usr/local/lib/python3.8/site-packages/django/core/management/__init__.py", line 442, in execute_from_command_line
tp-igl-backend  |     utility.execute()
tp-igl-backend  |   File "/usr/local/lib/python3.8/site-packages/django/core/management/__init__.py", line 436, in execute
tp-igl-backend  |     self.fetch_command(subcommand).run_from_argv(self.argv)
tp-igl-backend  |   File "/usr/local/lib/python3.8/site-packages/django/core/management/base.py", line 412, in run_from_argv
tp-igl-backend  |     self.execute(*args, **cmd_options)
tp-igl-backend  |   File "/usr/local/lib/python3.8/site-packages/django/core/management/base.py", line 458, in execute
tp-igl-backend  |     output = self.handle(*args, **options)
tp-igl-backend  |   File "/usr/local/lib/python3.8/site-packages/django/core/management/base.py", line 106, in wrapper
tp-igl-backend  |     res = handle_func(*args, **kwargs)
tp-igl-backend  |   File "/usr/local/lib/python3.8/site-packages/django/core/management/commands/migrate.py", line 100, in handle
tp-igl-backend  |     self.check(databases=[database])
tp-igl-backend  |   File "/usr/local/lib/python3.8/site-packages/django/core/management/base.py", line 485, in check
tp-igl-backend  |     all_issues = checks.run_checks(
tp-igl-backend  |   File "/usr/local/lib/python3.8/site-packages/django/core/checks/registry.py", line 88, in run_checks
tp-igl-backend  |     new_errors = check(app_configs=app_configs, databases=databases)
tp-igl-backend  |   File "/usr/local/lib/python3.8/site-packages/django/core/checks/database.py", line 13, in check_database_backends
tp-igl-backend  |     issues.extend(conn.validation.check(**kwargs))
tp-igl-backend  |   File "/usr/local/lib/python3.8/site-packages/django/db/backends/mysql/validation.py", line 9, in check
tp-igl-backend  |     issues.extend(self._check_sql_mode(**kwargs))
tp-igl-backend  |   File "/usr/local/lib/python3.8/site-packages/django/db/backends/mysql/validation.py", line 14, in _check_sql_mode
tp-igl-backend  |     self.connection.sql_mode & {"STRICT_TRANS_TABLES", "STRICT_ALL_TABLES"}
tp-igl-backend  |   File "/usr/local/lib/python3.8/site-packages/django/utils/functional.py", line 57, in __get__
tp-igl-backend  |     res = instance.__dict__[self.name] = self.func(instance)
tp-igl-backend  |   File "/usr/local/lib/python3.8/site-packages/django/db/backends/mysql/base.py", line 443, in sql_mode
tp-igl-backend  |     sql_mode = self.mysql_server_data["sql_mode"]
tp-igl-backend  |   File "/usr/local/lib/python3.8/site-packages/django/utils/functional.py", line 57, in __get__
tp-igl-backend  |     res = instance.__dict__[self.name] = self.func(instance)
tp-igl-backend  |   File "/usr/local/lib/python3.8/site-packages/django/db/backends/mysql/base.py", line 399, in mysql_server_data
tp-igl-backend  |     with self.temporary_connection() as cursor:
tp-igl-backend  |   File "/usr/local/lib/python3.8/contextlib.py", line 113, in __enter__
tp-igl-backend  |     return next(self.gen)
tp-igl-backend  |   File "/usr/local/lib/python3.8/site-packages/django/db/backends/base/base.py", line 705, in temporary_connection
tp-igl-backend  |     with self.cursor() as cursor:
tp-igl-backend  |   File "/usr/local/lib/python3.8/site-packages/django/utils/asyncio.py", line 26, in inner
tp-igl-backend  |     return func(*args, **kwargs)
tp-igl-backend  |   File "/usr/local/lib/python3.8/site-packages/django/db/backends/base/base.py", line 330, in cursor
tp-igl-backend  |     return self._cursor()
tp-igl-backend  |   File "/usr/local/lib/python3.8/site-packages/django/db/backends/base/base.py", line 306, in _cursor
tp-igl-backend  |     self.ensure_connection()
tp-igl-backend  |   File "/usr/local/lib/python3.8/site-packages/django/utils/asyncio.py", line 26, in inner
tp-igl-backend  |     return func(*args, **kwargs)
tp-igl-backend  |   File "/usr/local/lib/python3.8/site-packages/django/db/backends/base/base.py", line 289, in ensure_connection
tp-igl-backend  |     self.connect()
tp-igl-backend  |   File "/usr/local/lib/python3.8/site-packages/django/db/utils.py", line 91, in __exit__
tp-igl-backend  |     raise dj_exc_value.with_traceback(traceback) from exc_value
tp-igl-backend  |   File "/usr/local/lib/python3.8/site-packages/django/db/backends/base/base.py", line 289, in ensure_connection
tp-igl-backend  |     self.connect()
tp-igl-backend  |   File "/usr/local/lib/python3.8/site-packages/django/utils/asyncio.py", line 26, in inner
tp-igl-backend  |     return func(*args, **kwargs)
tp-igl-backend  |   File "/usr/local/lib/python3.8/site-packages/django/db/backends/base/base.py", line 270, in connect
tp-igl-backend  |     self.connection = self.get_new_connection(conn_params)
tp-igl-backend  |   File "/usr/local/lib/python3.8/site-packages/django/utils/asyncio.py", line 26, in inner
tp-igl-backend  |     return func(*args, **kwargs)
tp-igl-backend  |   File "/usr/local/lib/python3.8/site-packages/django/db/backends/mysql/base.py", line 247, in get_new_connection
tp-igl-backend  |     connection = Database.connect(**conn_params)
tp-igl-backend  |   File "/usr/local/lib/python3.8/site-packages/MySQLdb/__init__.py", line 121, in Connect
tp-igl-backend  |     return Connection(*args, **kwargs)
tp-igl-backend  |   File "/usr/local/lib/python3.8/site-packages/MySQLdb/connections.py", line 193, in __init__
tp-igl-backend  |     super().__init__(*args, **kwargs2)
tp-igl-backend  | django.db.utils.OperationalError: (2002, "Can't connect to local server through socket '/run/mysqld/mysqld.sock' (2)")
tp-igl-backend  | Traceback (most recent call last):
tp-igl-backend  |   File "/usr/local/lib/python3.8/site-packages/django/db/backends/base/base.py", line 289, in ensure_connection
tp-igl-backend  |     self.connect()
tp-igl-backend  |   File "/usr/local/lib/python3.8/site-packages/django/utils/asyncio.py", line 26, in inner
tp-igl-backend  |     return func(*args, **kwargs)
tp-igl-backend  |   File "/usr/local/lib/python3.8/site-packages/django/db/backends/base/base.py", line 270, in connect
tp-igl-backend  |     self.connection = self.get_new_connection(conn_params)
tp-igl-backend  |   File "/usr/local/lib/python3.8/site-packages/django/utils/asyncio.py", line 26, in inner
tp-igl-backend  |     return func(*args, **kwargs)
tp-igl-backend  |   File "/usr/local/lib/python3.8/site-packages/django/db/backends/mysql/base.py", line 247, in get_new_connection
tp-igl-backend  |     connection = Database.connect(**conn_params)
tp-igl-backend  |   File "/usr/local/lib/python3.8/site-packages/MySQLdb/__init__.py", line 121, in Connect
tp-igl-backend  |     return Connection(*args, **kwargs)
tp-igl-backend  |   File "/usr/local/lib/python3.8/site-packages/MySQLdb/connections.py", line 193, in __init__
tp-igl-backend  |     super().__init__(*args, **kwargs2)
tp-igl-backend  | MySQLdb.OperationalError: (2002, "Can't connect to local server through socket '/run/mysqld/mysqld.sock' (2)")
tp-igl-backend  | 
tp-igl-backend  | The above exception was the direct cause of the following exception:
tp-igl-backend  | 
tp-igl-backend  | Traceback (most recent call last):
tp-igl-backend  |   File "manage.py", line 22, in <module>
tp-igl-backend  |     main()
tp-igl-backend  |   File "manage.py", line 18, in main
tp-igl-backend  |     execute_from_command_line(sys.argv)
tp-igl-backend  |   File "/usr/local/lib/python3.8/site-packages/django/core/management/__init__.py", line 442, in execute_from_command_line
tp-igl-backend  |     utility.execute()
tp-igl-backend  |   File "/usr/local/lib/python3.8/site-packages/django/core/management/__init__.py", line 436, in execute
tp-igl-backend  |     self.fetch_command(subcommand).run_from_argv(self.argv)
tp-igl-backend  |   File "/usr/local/lib/python3.8/site-packages/django/core/management/base.py", line 412, in run_from_argv
tp-igl-backend  |     self.execute(*args, **cmd_options)
tp-igl-backend  |   File "/usr/local/lib/python3.8/site-packages/django/core/management/base.py", line 458, in execute
tp-igl-backend  |     output = self.handle(*args, **options)
tp-igl-backend  |   File "/usr/local/lib/python3.8/site-packages/django/core/management/base.py", line 106, in wrapper
tp-igl-backend  |     res = handle_func(*args, **kwargs)
tp-igl-backend  |   File "/usr/local/lib/python3.8/site-packages/django/core/management/commands/migrate.py", line 100, in handle
tp-igl-backend  |     self.check(databases=[database])
tp-igl-backend  |   File "/usr/local/lib/python3.8/site-packages/django/core/management/base.py", line 485, in check
tp-igl-backend  |     all_issues = checks.run_checks(
tp-igl-backend  |   File "/usr/local/lib/python3.8/site-packages/django/core/checks/registry.py", line 88, in run_checks
tp-igl-backend  |     new_errors = check(app_configs=app_configs, databases=databases)
tp-igl-backend  |   File "/usr/local/lib/python3.8/site-packages/django/core/checks/database.py", line 13, in check_database_backends
tp-igl-backend  |     issues.extend(conn.validation.check(**kwargs))
tp-igl-backend  |   File "/usr/local/lib/python3.8/site-packages/django/db/backends/mysql/validation.py", line 9, in check
tp-igl-backend  |     issues.extend(self._check_sql_mode(**kwargs))
tp-igl-backend  |   File "/usr/local/lib/python3.8/site-packages/django/db/backends/mysql/validation.py", line 14, in _check_sql_mode
tp-igl-backend  |     self.connection.sql_mode & {"STRICT_TRANS_TABLES", "STRICT_ALL_TABLES"}
tp-igl-backend  |   File "/usr/local/lib/python3.8/site-packages/django/utils/functional.py", line 57, in __get__
tp-igl-backend  |     res = instance.__dict__[self.name] = self.func(instance)
tp-igl-backend  |   File "/usr/local/lib/python3.8/site-packages/django/db/backends/mysql/base.py", line 443, in sql_mode
tp-igl-backend  |     sql_mode = self.mysql_server_data["sql_mode"]
tp-igl-backend  |   File "/usr/local/lib/python3.8/site-packages/django/utils/functional.py", line 57, in __get__
tp-igl-backend  |     res = instance.__dict__[self.name] = self.func(instance)
tp-igl-backend  |   File "/usr/local/lib/python3.8/site-packages/django/db/backends/mysql/base.py", line 399, in mysql_server_data
tp-igl-backend  |     with self.temporary_connection() as cursor:
tp-igl-backend  |   File "/usr/local/lib/python3.8/contextlib.py", line 113, in __enter__
tp-igl-backend  |     return next(self.gen)
tp-igl-backend  |   File "/usr/local/lib/python3.8/site-packages/django/db/backends/base/base.py", line 705, in temporary_connection
tp-igl-backend  |     with self.cursor() as cursor:
tp-igl-backend  |   File "/usr/local/lib/python3.8/site-packages/django/utils/asyncio.py", line 26, in inner
tp-igl-backend  |     return func(*args, **kwargs)
tp-igl-backend  |   File "/usr/local/lib/python3.8/site-packages/django/db/backends/base/base.py", line 330, in cursor
tp-igl-backend  |     return self._cursor()
tp-igl-backend  |   File "/usr/local/lib/python3.8/site-packages/django/db/backends/base/base.py", line 306, in _cursor
tp-igl-backend  |     self.ensure_connection()
tp-igl-backend  |   File "/usr/local/lib/python3.8/site-packages/django/utils/asyncio.py", line 26, in inner
tp-igl-backend  |     return func(*args, **kwargs)
tp-igl-backend  |   File "/usr/local/lib/python3.8/site-packages/django/db/backends/base/base.py", line 289, in ensure_connection
tp-igl-backend  |     self.connect()
tp-igl-backend  |   File "/usr/local/lib/python3.8/site-packages/django/db/utils.py", line 91, in __exit__
tp-igl-backend  |     raise dj_exc_value.with_traceback(traceback) from exc_value
tp-igl-backend  |   File "/usr/local/lib/python3.8/site-packages/django/db/backends/base/base.py", line 289, in ensure_connection
tp-igl-backend  |     self.connect()
tp-igl-backend  |   File "/usr/local/lib/python3.8/site-packages/django/utils/asyncio.py", line 26, in inner
tp-igl-backend  |     return func(*args, **kwargs)
tp-igl-backend  |   File "/usr/local/lib/python3.8/site-packages/django/db/backends/base/base.py", line 270, in connect
tp-igl-backend  |     self.connection = self.get_new_connection(conn_params)
tp-igl-backend  |   File "/usr/local/lib/python3.8/site-packages/django/utils/asyncio.py", line 26, in inner
tp-igl-backend  |     return func(*args, **kwargs)
tp-igl-backend  |   File "/usr/local/lib/python3.8/site-packages/django/db/backends/mysql/base.py", line 247, in get_new_connection
tp-igl-backend  |     connection = Database.connect(**conn_params)
tp-igl-backend  |   File "/usr/local/lib/python3.8/site-packages/MySQLdb/__init__.py", line 121, in Connect
tp-igl-backend  |     return Connection(*args, **kwargs)
tp-igl-backend  |   File "/usr/local/lib/python3.8/site-packages/MySQLdb/connections.py", line 193, in __init__
tp-igl-backend  |     super().__init__(*args, **kwargs2)
tp-igl-backend  | django.db.utils.OperationalError: (2002, "Can't connect to local server through socket '/run/mysqld/mysqld.sock' (2)")
